Workbook

Sheet Ответы
A1: Отметка времени | B1: Ваш возраст? | C1: Род деятельности? | D1: Как часто вы читаете книги? | E1: Сколько книг вы прочитываете за год? | F1: В каком формате вы читаете? | G1: Где и когда вы чаще всего читаете или выбираете, что читать? | H1: С какой целью вы читаете? | I1: Откуда вы обычно узнаёте о новых книгах? | J1: Насколько вам сложно выбрать, что прочитать дальше? | K1: С какими трудностями вы сталкиваетесь при выборе книги? | L1: Какие жанры вам интересны? | M1: Пользовались ли вы раньше сервисами рекомендации книг? | N1: Что для вас важнее всего в сервисе рекомендации книг? | O1: Как вам удобнее пользоваться таким сервисом?
A2: 46314.772 | B2: 35-44 | C2: Работаю | D2: Несколько раз в год | E2: 3-6 | F2: Бумажные книги | G2: В отпуске / на выходных | H2: Для удовольствия и отдыха | I2: Рейтинги и подборки на сайтах | J2: Совсем не сложно | K2: Мало времени на поиск, Трудностей нет | L2: Романы | M2: Пробовал(а) несколько раз | N2: Точность рекомендаций под мои вкусы | O2: Мобильное приложение
A3: 46314.772 | B3: 35-44 | C3: Работаю | D3: Несколько раз в год | E3: 3-6 | F3: Бумажные книги | G3: В отпуске / на выходных | H3: Для удовольствия и отдыха | I3: Рейтинги и подборки на сайтах | J3: Совсем не сложно | K3: Мало времени на поиск, Трудностей нет | L3: Романы | M3: Пробовал(а) несколько раз | N3: Точность рекомендаций под мои вкусы | O3: Мобильное приложение
A4: 46314.779 | B4: 18-24 | C4: Студент | D4: Практически не читаю | E4: 0-2 | F4: Бумажные книги | G4: Во время отдыха | H4: Для учёбы или работы | I4: Случайно, по обложке или названию | J4: Совсем не сложно | K4: Трудностей нет | L4: Фантастика и фэнтези, Бизнес и саморазвитие | M4: Да, пользуюсь регулярно | N4: Бесплатное использование | O4: Мобильное приложение
A5: 46314.782 | B5: До 18 лет | C5: Студент | D5: Практически не читаю | E5: 0-2 | F5: Не читаю | G5: Во время отдыха | H5: Чтобы скоротать время | I5: Советы друзей и близких | J5: Совсем не сложно | K5: Трудностей нет | L5: Учебная и профессиональная литература | M5: Нет, не знал(а) о них | N5: Простой и понятный интерфейс | O5: Без разницы
A6: 46314.782 | B6: 18-24 | C6: Студент | D6: Несколько раз в месяц | E6: 0-2 | F6: Бумажные книги, Аудиокниги | G6: Во время отдыха | H6: Для удовольствия и отдыха | I6: Советы друзей и близких | J6: Совсем не сложно | K6: Трудностей нет | L6: Фантастика и фэнтези, Классическая литература | M6: Нет, но слышал(а) о таких | N6: Отзывы и оценки других читателей, Возможность вести список прочитанного и «хочу прочитать» | O6: Сайт в браузере
A7: 46314.789 | B7: 18-24 | C7: Студент | D7: Несколько раз в месяц | E7: 0-2 | F7: Электронные книги | G7: Во время отдыха, Перед сном, В отпуске / на выходных | H7: Для удовольствия и отдыха, Для саморазвития | I7: Советы друзей и близких, Соцсети и блогеры, Рейтинги и подборки на сайтах, Случайно, по обложке или названию | J7: Скорее не сложно | K7: Трудностей нет | L7: Фантастика и фэнтези, Детективы, Романы, Бизнес и саморазвитие | M7: Пробовал(а) несколько раз | N7: Точность рекомендаций под мои вкусы, Возможность вести список прочитанного и «хочу прочитать», Подборки по настроению или теме | O7: Мобильное приложение
A8: 46314.793 | B8: 18-24 | C8: Студент | D8: Несколько раз в месяц | E8: 3-6 | F8: Электронные книги | G8: В перерывах между учёбой или работой | H8: Для учёбы или работы, Для саморазвития | I8: Рейтинги и подборки на сайтах | J8: Скорее не сложно | K8: Не знаю, что подойдёт именно мне, Рекомендации не совпадают с моими вкусами, Мало времени на поиск | L8: Фантастика и фэнтези, Детективы, Романы, Классическая литература, Научно-популярная литература | M8: Нет, но слышал(а) о таких | N8: Возможность сразу купить или скачать книгу, Бесплатное использование, Возможность вести список прочитанного и «хочу прочитать» | O8: Мобильное приложение
A9: 46314.798 | B9: До 18 лет | C9: Школьник | D9: Несколько раз в месяц | E9: 3-6 | F9: Электронные книги | G9: Перед сном, В перерывах между учёбой или работой | H9: Для учёбы или работы | I9: Советы друзей и близких, Соцсети и блогеры | J9: Скорее сложно | K9: Сложно найти книгу нужной тематики | L9: Фантастика и фэнтези, Детективы | M9: Нет, не знал(а) о них | N9: Точность рекомендаций под мои вкусы, Простой и понятный интерфейс, Отзывы и оценки других читателей, Возможность вести список прочитанного и «хочу прочитать», Подборки по настроению или теме | O9: Без разницы
A10: 46314.798 | B10: 18-24 | C10: Студент | D10: Несколько раз в месяц | E10: 3-6 | F10: Бумажные книги | G10: Во время отдыха, В отпуске / на выходных | H10: Для удовольствия и отдыха, Для саморазвития | I10: Советы друзей и близких, Соцсети и блогеры, Рекомендации в приложениях | J10: Совсем не сложно | K10: Не знаю, что подойдёт именно мне, Боюсь разочароваться и потратить деньги или время впустую | L10: Бизнес и саморазвитие, Учебная и профессиональная литература | M10: Нет, но слышал(а) о таких | N10: Точность рекомендаций под мои вкусы, Простой и понятный интерфейс, Возможность сразу купить или скачать книгу, Бесплатное использование, Возможность вести список прочитанного и «хочу прочитать» | O10: Мобильное приложение
A11: 46314.824 | B11: До 18 лет | C11: Студент | D11: Практически не читаю | E11: 0-2 | F11: Бумажные книги, Электронные книги, Аудиокниги, Не читаю, Хз | G11: Во время отдыха, Перед сном, В дороге, В перерывах между учёбой или работой, В отпуске / на выходных | H11: Для удовольствия и отдыха, Для учёбы или работы, Для саморазвития, Чтобы скоротать время, Чтобы обсуждать прочитанное с друзьями | I11: Советы друзей и близких, Соцсети и блогеры, Книжные магазины и библиотеки, Рейтинги и подборки на сайтах, Рекомендации в приложениях, Случайно, по обложке или названию | J11: Очень сложно | K11: Не знаю, что подойдёт именно мне, Рекомендации не совпадают с моими вкусами, Мало времени на поиск, Боюсь разочароваться и потратить деньги или время впустую, Сложно найти книгу нужной тематики, Трудностей нет | L11: Фантастика и фэнтези, Детективы, Романы, Современная проза, Триллеры, Классическая литература, Научно-популярная литература, Бизнес и саморазвитие, Учебная и профессиональная литература | M11: Нет, не знал(а) о них | N11: Точность рекомендаций под мои вкусы, Простой и понятный интерфейс, Отзывы и оценки других читателей, Возможность сразу купить или скачать книгу, Бесплатное использование, Возможность вести список прочитанного и «хочу прочитать», Подборки по настроению или теме, Общение с другими читателями | O11: Мобильное приложение
A12: 46314.884 | B12: До 18 лет | C12: Студент | D12: Несколько раз в месяц | E12: 3-6 | F12: Бумажные книги | G12: В отпуске / на выходных | H12: Для удовольствия и отдыха, Чтобы обсуждать прочитанное с друзьями | I12: Соцсети и блогеры | J12: Совсем не сложно | K12: Сложно найти книгу нужной тематики | L12: Фантастика и фэнтези, Детективы, Триллеры | M12: Да, пользуюсь регулярно | N12: Точность рекомендаций под мои вкусы, Подборки по настроению или теме | O12: Мобильное приложение
A13: 46315.431 | B13: 18-24 | C13: Студент | D13: Практически не читаю | E13: 0-2 | F13: Бумажные книги, Аудиокниги | G13: Перед сном, В дороге | H13: Для саморазвития, Чтобы скоротать время | I13: Случайно, по обложке или названию | J13: Скорее не сложно | K13: Боюсь разочароваться и потратить деньги или время впустую | L13: Фантастика и фэнтези, Бизнес и саморазвитие, Учебная и профессиональная литература | M13: Пробовал(а) несколько раз | N13: Точность рекомендаций под мои вкусы, Простой и понятный интерфейс, Отзывы и оценки других читателей, Бесплатное использование, Возможность вести список прочитанного и «хочу прочитать», Подборки по настроению или теме, Общение с другими читателями | O13: Мобильное приложение
A14: 46315.478 | B14: 18-24 | C14: Студент | D14: Несколько раз в год | E14: 0-2 | F14: Электронные книги, Аудиокниги | G14: В дороге | H14: Для удовольствия и отдыха, Чтобы скоротать время | I14: Рейтинги и подборки на сайтах, Рекомендации в приложениях | J14: Скорее сложно | K14: Рекомендации не совпадают с моими вкусами, Сложно найти книгу нужной тематики | L14: Фантастика и фэнтези, Романы | M14: Пробовал(а) несколько раз | N14: Простой и понятный интерфейс, Отзывы и оценки других читателей, Возможность вести список прочитанного и «хочу прочитать» | O14: Без разницы

Sheet Диаграммы
A1: 1. Ваш возраст?
A2: Всего респондентов: | B2: =COUNTA(Ответы!$B$2:$B$14) -> 13
A3: Вариант ответа | B3: Кол-во | C3: % респ.
A4: 18-24 | B4: =COUNTIF(Ответы!$B$2:$B$14,A4) -> 7 | C4: =B4/$B$2 -> 0.53846154
A5: До 18 лет | B5: =COUNTIF(Ответы!$B$2:$B$14,A5) -> 4 | C5: =B5/$B$2 -> 0.30769231
A6: 35-44 | B6: =COUNTIF(Ответы!$B$2:$B$14,A6) -> 2 | C6: =B6/$B$2 -> 0.15384615
A18: 2. Род деятельности?
A19: Всего респондентов: | B19: =COUNTA(Ответы!$C$2:$C$14) -> 13
A20: Вариант ответа | B20: Кол-во | C20: % респ.
A21: Студент | B21: =COUNTIF(Ответы!$C$2:$C$14,A21) -> 10 | C21: =B21/$B$19 -> 0.76923077
A22: Работаю | B22: =COUNTIF(Ответы!$C$2:$C$14,A22) -> 2 | C22: =B22/$B$19 -> 0.15384615
A23: Школьник | B23: =COUNTIF(Ответы!$C$2:$C$14,A23) -> 1 | C23: =B23/$B$19 -> 0.076923077
A35: 3. Как часто вы читаете книги?
A36: Всего респондентов: | B36: =COUNTA(Ответы!$D$2:$D$14) -> 13
A37: Вариант ответа | B37: Кол-во | C37: % респ.
A38: Несколько раз в месяц | B38: =COUNTIF(Ответы!$D$2:$D$14,A38) -> 6 | C38: =B38/$B$36 -> 0.46153846
A39: Практически не читаю | B39: =COUNTIF(Ответы!$D$2:$D$14,A39) -> 4 | C39: =B39/$B$36 -> 0.30769231
A40: Несколько раз в год | B40: =COUNTIF(Ответы!$D$2:$D$14,A40) -> 3 | C40: =B40/$B$36 -> 0.23076923
A52: 4. Сколько книг вы прочитываете за год?
A53: Всего респондентов: | B53: =COUNTA(Ответы!$E$2:$E$14) -> 13
A54: Вариант ответа | B54: Кол-во | C54: % респ.
A55: 0-2 | B55: =COUNTIF(Ответы!$E$2:$E$14,A55) -> 7 | C55: =B55/$B$53 -> 0.53846154
A56: 3-6 | B56: =COUNTIF(Ответы!$E$2:$E$14,A56) -> 6 | C56: =B56/$B$53 -> 0.46153846
A69: 5. В каком формате вы читаете?
A70: Всего респондентов: | B70: =COUNTA(Ответы!$F$2:$F$14) -> 13 | C70: можно несколько вариантов
A71: Вариант ответа | B71: Кол-во | C71: % респ.
A72: Бумажные книги | B72: =COUNTIF(Ответы!$F$2:$F$14,"*"&A72&"*") -> 8 | C72: =B72/$B$70 -> 0.61538462
A73: Электронные книги | B73: =COUNTIF(Ответы!$F$2:$F$14,"*"&A73&"*") -> 5 | C73: =B73/$B$70 -> 0.38461538
A74: Аудиокниги | B74: =COUNTIF(Ответы!$F$2:$F$14,"*"&A74&"*") -> 4 | C74: =B74/$B$70 -> 0.30769231
A75: Не читаю | B75: =COUNTIF(Ответы!$F$2:$F$14,"*"&A75&"*") -> 2 | C75: =B75/$B$70 -> 0.15384615
A76: Хз | B76: =COUNTIF(Ответы!$F$2:$F$14,"*"&A76&"*") -> 1 | C76: =B76/$B$70 -> 0.076923077
A86: 6. Где и когда вы чаще всего читаете или выбираете, что читать?
A87: Всего респондентов: | B87: =COUNTA(Ответы!$G$2:$G$14) -> 13 | C87: можно несколько вариантов
A88: Вариант ответа | B88: Кол-во | C88: % респ.
A89: В отпуске / на выходных | B89: =COUNTIF(Ответы!$G$2:$G$14,"*"&A89&"*") -> 6 | C89: =B89/$B$87 -> 0.46153846
A90: Во время отдыха | B90: =COUNTIF(Ответы!$G$2:$G$14,"*"&A90&"*") -> 6 | C90: =B90/$B$87 -> 0.46153846
A91: Перед сном | B91: =COUNTIF(Ответы!$G$2:$G$14,"*"&A91&"*") -> 4 | C91: =B91/$B$87 -> 0.30769231
A92: В дороге | B92: =COUNTIF(Ответы!$G$2:$G$14,"*"&A92&"*") -> 3 | C92: =B92/$B$87 -> 0.23076923
A93: В перерывах между учёбой или работой | B93: =COUNTIF(Ответы!$G$2:$G$14,"*"&A93&"*") -> 3 | C93: =B93/$B$87 -> 0.23076923
A103: 7. С какой целью вы читаете?
...
